Workbook

Sheet HO,A.A SHOP
A1: LeapFrog Software Technology Africa PLC
A2: Payroll Sheet Head office and A.A shop
A3: For the Month of June 2026/Sene 2018
A5: No. | B5: Name of Employees | C5: Position | D5: Shop Name | E5: Working days | F5: Basic Salary | G5: Monthly Salary | H5: Commiss. /OT | I5: KPI | J5: Gross Salary | K5: Taxable Income | L5: Income Tax | M5: Pension 7% | N5: Pension 11% | O5: Shortage/ Loan | P5: Total Deduction | Q5: Transport & other allowance | R5: Net Pay | S5: sign
A6: 1 | B6: Abaynesh Abera | C6: Cleaner | D6: 4KILO | E6: 30 | F6: 3695.2 | G6: =+F6/30*E6 -> 3695.2 | J6: =G6+H6+I6 -> 3695.2 | K6: =G6+H6+I6 -> 3695.2 | L6: =IF(K6<=2000,(0),IF(K6<=4000,(K6*0.15)-300,IF(K6<=7000,(K6*0.2)-500,IF(K6<=10000,(K6*0.25)-850,IF(K6<=14000,(K6*0.3)-1350,IF(K6>14000,(K6*0.35)-2050)))))) -> 254.28 | M6: =F6*0.07 -> 258.664 | N6: =F6*0.11 -> 406.472 | P6: =L6+M6+O6 -> 512.944 | R6: =J6-P6+Q6 -> 3182.256
A7: 2 | B7: Abebu Shumye | C7: Cleaner | D7: BoleArabsa | E7: 30 | F7: 2179.49 | G7: =+F7/30*E7 -> 2179.49 | J7: =G7+H7+I7 -> 2179.49 | K7: =G7+H7+I7 -> 2179.49 | L7: =IF(K7<=2000,(0),IF(K7<=4000,(K7*0.15)-300,IF(K7<=7000,(K7*0.2)-500,IF(K7<=10000,(K7*0.25)-850,IF(K7<=14000,(K7*0.3)-1350,IF(K7>14000,(K7*0.35)-2050)))))) -> 26.9235 | M7: =F7*0.07 -> 152.5643 | N7: =F7*0.11 -> 239.7439 | P7: =L7+M7+O7 -> 179.4878 | R7: =J7-P7+Q7 -> 2000.0022
A8: 3 | B8: Abel Gezahegn | C8: SM | D8: Abado | E8: 30 | F8: 21724.14 | G8: =+F8/30*E8 -> 21724.14 | H8: 4000 | I8: =1846.15*0 -> 0 | J8: =G8+H8+I8 -> 25724.14 | K8: =G8+H8+I8 -> 25724.14 | L8: =IF(K8<=2000,(0),IF(K8<=4000,(K8*0.15)-300,IF(K8<=7000,(K8*0.2)-500,IF(K8<=10000,(K8*0.25)-850,IF(K8<=14000,(K8*0.3)-1350,IF(K8>14000,(K8*0.35)-2050)))))) -> 6953.449 | M8: =F8*0.07 -> 1520.6898 | N8: =F8*0.11 -> 2389.6554 | P8: =L8+M8+O8 -> 8474.1388 | Q8: 2000 | R8: =J8-P8+Q8 -> 19250.001
A9: 4 | B9: Abezash Yeneneh | C9: Cleaner | D9: Wessen | E9: 30 | F9: 2179.49 | G9: =+F9/30*E9 -> 2179.49 | J9: =G9+H9+I9 -> 2179.49 | K9: =G9+H9+I9 -> 2179.49 | L9: =IF(K9<=2000,(0),IF(K9<=4000,(K9*0.15)-300,IF(K9<=7000,(K9*0.2)-500,IF(K9<=10000,(K9*0.25)-850,IF(K9<=14000,(K9*0.3)-1350,IF(K9>14000,(K9*0.35)-2050)))))) -> 26.9235 | M9: =F9*0.07 -> 152.5643 | N9: =F9*0.11 -> 239.7439 | P9: =L9+M9+O9 -> 179.4878 | Q9: 500 | R9: =J9-P9+Q9 -> 2500.0022
A10: 5 | B10: Abdurehman Assefa | C10: BA coordinator | D10: 4KILO | E10: 30 | F10: 4794.52 | G10: =+F10/30*E10 -> 4794.52 | I10: =2654.34*0.5 -> 1327.17 | J10: =G10+H10+I10 -> 6121.69 | K10: =G10+H10+I10 -> 6121.69 | L10: =IF(K10<=2000,(0),IF(K10<=4000,(K10*0.15)-300,IF(K10<=7000,(K10*0.2)-500,IF(K10<=10000,(K10*0.25)-850,IF(K10<=14000,(K10*0.3)-1350,IF(K10>14000,(K10*0.35)-2050)))))) -> 724.338 | M10: =F10*0.07 -> 335.6164 | N10: =F10*0.11 -> 527.3972 | P10: =L10+M10+O10 -> 1059.9544 | Q10: =1000/30*E10 -> 1000 | R10: =J10-P10+Q10 -> 6061.7356
A11: 6 | B11: Adelal Muhabaw | C11: BA coordinator | D11: Kara | E11: 30 | F11: 4794.52 | G11: =+F11/30*E11 -> 4794.52 | I11: =2654.34*0.5 -> 1327.17 | J11: =G11+H11+I11 -> 6121.69 | K11: =G11+H11+I11 -> 6121.69 | L11: =IF(K11<=2000,(0),IF(K11<=4000,(K11*0.15)-300,IF(K11<=7000,(K11*0.2)-500,IF(K11<=10000,(K11*0.25)-850,IF(K11<=14000,(K11*0.3)-1350,IF(K11>14000,(K11*0.35)-2050)))))) -> 724.338 | P11: =L11+M11+O11 -> 724.338 | Q11: =1000/30*E11 -> 1000 | R11: =J11-P11+Q11 -> 6397.352
A12: 7 | B12: Alemi Yadafa | C12: Cleaner | D12: BoleArabsa | E12: 30 | F12: 1612.9 | G12: =+F12/30*E12 -> 1612.9 | J12: =G12+H12+I12 -> 1612.9 | K12: =G12+H12+I12 -> 1612.9 | L12: =IF(K12<=2000,(0),IF(K12<=4000,(K12*0.15)-300,IF(K12<=7000,(K12*0.2)-500,IF(K12<=10000,(K12*0.25)-850,IF(K12<=14000,(K12*0.3)-1350,IF(K12>14000,(K12*0.35)-2050)))))) -> 0 | M12: =F12*0.07 -> 112.903 | N12: =F12*0.11 -> 177.419 | P12: =L12+M12+O12 -> 112.903 | R12: =J12-P12+Q12 -> 1499.997
A13: 8 | B13: Alem Seifu | C13: Cleaner | D13: 6KILO | E13: 30 | F13: 1612.9 | G13: =+F13/30*E13 -> 1612.9 | J13: =G13+H13+I13 -> 1612.9 | K13: =G13+H13+I13 -> 1612.9 | L13: =IF(K13<=2000,(0),IF(K13<=4000,(K13*0.15)-300,IF(K13<=7000,(K13*0.2)-500,IF(K13<=10000,(K13*0.25)-850,IF(K13<=14000,(K13*0.3)-1350,IF(K13>14000,(K13*0.35)-2050)))))) -> 0 | M13: =F13*0.07 -> 112.903 | N13: =F13*0.11 -> 177.419 | P13: =L13+M13+O13 -> 112.903 | R13: =J13-P13+Q13 -> 1499.997
A14: 9 | B14: Alemnesh Asfaw | C14: DSP | D14: Kara | E14: 30 | F14: 8007.94 | G14: =+F14/30*E14 -> 8007.94 | I14: =2857.14*1 -> 2857.14 | J14: =G14+H14+I14 -> 10865.08 | K14: =G14+H14+I14 -> 10865.08 | L14: =IF(K14<=2000,(0),IF(K14<=4000,(K14*0.15)-300,IF(K14<=7000,(K14*0.2)-500,IF(K14<=10000,(K14*0.25)-850,IF(K14<=14000,(K14*0.3)-1350,IF(K14>14000,(K14*0.35)-2050)))))) -> 1909.524 | M14: =F14*0.07 -> 560.5558 | N14: =F14*0.11 -> 880.8734 | P14: =L14+M14+O14 -> 2470.0798 | Q14: 1000 | R14: =J14-P14+Q14 -> 9395.0002
A15: 10 | B15: Alemtsehay Ashine | C15: HR MANAGER | D15: Head Office | E15: 30 | F15: 82672.41 | G15: =+F15/30*E15 -> 82672.41 | J15: =G15+H15+I15 -> 82672.41 | K15: =G15+H15+I15 -> 82672.41 | L15: =IF(K15<=2000,(0),IF(K15<=4000,(K15*0.15)-300,IF(K15<=7000,(K15*0.2)-500,IF(K15<=10000,(K15*0.25)-850,IF(K15<=14000,(K15*0.3)-1350,IF(K15>14000,(K15*0.35)-2050)))))) -> 26885.343 | M15: =F15*0.07 -> 5787.0687 | N15: =F15*0.11 -> 9093.9651 | P15: =L15+M15+O15 -> 32672.412 | Q15: =2000 -> 2000 | R15: =J15-P15+Q15 -> 51999.998
A16: 11 | B16: Amanuel Abebe | C16: HR OFFICER | D16: Head Office | E16: 30 | F16: 26594.82 | G16: =+F16/30*E16 -> 26594.82 | J16: =G16+H16+I16 -> 26594.82 | K16: =G16+H16+I16 -> 26594.82 | L16: =IF(K16<=2000,(0),IF(K16<=4000,(K16*0.15)-300,IF(K16<=7000,(K16*0.2)-500,IF(K16<=10000,(K16*0.25)-850,IF(K16<=14000,(K16*0.3)-1350,IF(K16>14000,(K16*0.35)-2050)))))) -> 7258.187 | M16: =F16*0.07 -> 1861.6374 | N16: =F16*0.11 -> 2925.4302 | P16: =L16+M16+O16 -> 9119.8244 | Q16: 1000 | R16: =J16-P16+Q16 -> 18474.996
A17: 12 | B17: Andualem Assefa | C17: Finance Director | D17: Head Office | E17: 30 | F17: 110258.62 | G17: =+F17/30*E17 -> 110258.62 | I17: 23076.92 | J17: =G17+H17+I17 -> 133335.54 | K17: =G17+H17+I17 -> 133335.54 | L17: =IF(K17<=2000,(0),IF(K17<=4000,(K17*0.15)-300,IF(K17<=7000,(K17*0.2)-500,IF(K17<=10000,(K17*0.25)-850,IF(K17<=14000,(K17*0.3)-1350,IF(K17>14000,(K17*0.35)-2050)))))) -> 44617.439 | M17: =F17*0.07 -> 7718.1034 | N17: =F17*0.11 -> 12128.448 | P17: =L17+M17+O17 -> 52335.542 | Q17: 4000 | R17: =J17-P17+Q17 -> 84999.998
A18: 13 | B18: Andualem Getachew | C18: IT | D18: Head Office | E18: 30 | F18: 48189.66 | G18: =+F18/30*E18 -> 48189.66 | J18: =G18+H18+I18 -> 48189.66 | K18: =G18+H18+I18 -> 48189.66 | L18: =IF(K18<=2000,(0),IF(K18<=4000,(K18*0.15)-300,IF(K18<=7000,(K18*0.2)-500,IF(K18<=10000,(K18*0.25)-850,IF(K18<=14000,(K18*0.3)-1350,IF(K18>14000,(K18*0.35)-2050)))))) -> 14816.381 | M18: =F18*0.07 -> 3373.2762 | P18: =L18+M18+O18 -> 18189.657 | Q18: =2000+1000 -> 3000 | R18: =J18-P18+Q18 -> 33000.003
A19: 14 | B19: Asiya Abera | C19: SM | D19: Shiromeda | E19: 30 | F19: 21724.14 | G19: =+F19/30*E19 -> 21724.14 | I19: =1846.15*0 -> 0 | J19: =G19+H19+I19 -> 21724.14 | K19: =G19+H19+I19 -> 21724.14 | L19: =IF(K19<=2000,(0),IF(K19<=4000,(K19*0.15)-300,IF(K19<=7000,(K19*0.2)-500,IF(K19<=10000,(K19*0.25)-850,IF(K19<=14000,(K19*0.3)-1350,IF(K19>14000,(K19*0.35)-2050)))))) -> 5553.449 | M19: =F19*0.07 -> 1520.6898 | N19: =F19*0.11 -> 2389.6554 | P19: =L19+M19+O19 -> 7074.1388 | Q19: =2000 -> 2000 | R19: =J19-P19+Q19 -> 16650.001
A20: 15 | B20: Atalel Talasebaw | C20: Cleaner | D20: AYAT49 | E20: 30 | F20: 1612.9 | G20: =+F20/30*E20 -> 1612.9 | J20: =G20+H20+I20 -> 1612.9 | K20: =G20+H20+I20 -> 1612.9 | L20: =IF(K20<=2000,(0),IF(K20<=4000,(K20*0.15)-300,IF(K20<=7000,(K20*0.2)-500,IF(K20<=10000,(K20*0.25)-850,IF(K20<=14000,(K20*0.3)-1350,IF(K20>14000,(K20*0.35)-2050)))))) -> 0 | M20: =F20*0.07 -> 112.903 | N20: =F20*0.11 -> 177.419 | P20: =L20+M20+O20 -> 112.903 | R20: =J20-P20+Q20 -> 1499.997
A21: 16 | B21: Aynalem Bayssa Feyssa | C21: Accountant | D21: Head Office | E21: 30 | F21: 17155.17 | G21: =+F21/30*E21 -> 17155.17 | J21: =G21+H21+I21 -> 17155.17 | K21: =G21+H21+I21 -> 17155.17 | L21: =IF(K21<=2000,(0),IF(K21<=4000,(K21*0.15)-300,IF(K21<=7000,(K21*0.2)-500,IF(K21<=10000,(K21*0.25)-850,IF(K21<=14000,(K21*0.3)-1350,IF(K21>14000,(K21*0.35)-2050)))))) -> 3954.3095 | M21: =F21*0.07 -> 1200.8619 | N21: =F21*0.11 -> 1887.0687 | P21: =L21+M21+O21 -> 5155.1714 | Q21: 1500 | R21: =J21-P21+Q21 -> 13499.999
A22: 17 | B22: Betelhem Million | C22: DSP | D22: Megenagna | E22: 30 | F22: 8007.94 | G22: =+F22/30*E22 -> 8007.94 | I22: =2857.14/30*E22 -> 2857.14 | J22: =G22+H22+I22 -> 10865.08 | K22: =G22+H22+I22 -> 10865.08 | L22: =IF(K22<=2000,(0),IF(K22<=4000,(K22*0.15)-300,IF(K22<=7000,(K22*0.2)-500,IF(K22<=10000,(K22*0.25)-850,IF(K22<=14000,(K22*0.3)-1350,IF(K22>14000,(K22*0.35)-2050)))))) -> 1909.524 | M22: =F22*0.07 -> 560.5558 | N22: =F22*0.11 -> 880.8734 | P22: =L22+M22+O22 -> 2470.0798 | Q22: =1000 -> 1000 | R22: =J22-P22+Q22 -> 9395.0002
A23: 18 | B23: Betelhem Tesfaye | C23: S.Accountant | D23: AyatTafo | E23: 30 | F23: 11108.37 | G23: =+F23/30*E23 -> 11108.37 | I23: =2857.14 -> 2857.14 | J23: =G23+H23+I23 -> 13965.51 | K23: =G23+H23+I23 -> 13965.51 | L23: =IF(K23<=2000,(0),IF(K23<=4000,(K23*0.15)-300,IF(K23<=7000,(K23*0.2)-500,IF(K23<=10000,(K23*0.25)-850,IF(K23<=14000,(K23*0.3)-1350,IF(K23>14000,(K23*0.35)-2050)))))) -> 2839.653 | M23: =F23*0.07 -> 777.5859 | N23: =F23*0.11 -> 1221.9207 | P23: =L23+M23+O23 -> 3617.2389 | Q23: =1000+1200+740 -> 2940 | R23: =J23-P23+Q23 -> 13288.271
A24: 19 | B24: Belge Mola | C24: BA coordinator | D24: H/mariam | E24: 30 | F24: 4794.52 | G24: =+F24/30*E24 -> 4794.52 | I24: =2654.34/30*E24 -> 2654.34 | J24: =G24+H24+I24 -> 7448.86 | K24: =G24+H24+I24 -> 7448.86 | L24: =IF(K24<=2000,(0),IF(K24<=4000,(K24*0.15)-300,IF(K24<=7000,(K24*0.2)-500,IF(K24<=10000,(K24*0.25)-850,IF(K24<=14000,(K24*0.3)-1350,IF(K24>14000,(K24*0.35)-2050)))))) -> 1012.215 | M24: =F24*0.07 -> 335.6164 | N24: =F24*0.11 -> 527.3972 | P24: =L24+M24+O24 -> 1347.8314 | Q24: =1000/30*E24 -> 1000 | R24: =J24-P24+Q24 -> 7101.0286
A25: 20 | B25: Bogal Bekele | C25: Security | D25: Fiyelbet | E25: 30 | F25: 5084.07 | G25: =+F25/30*E25 -> 5084.07 | H25: =Overtime!I5 -> 2933.1173 | J25: =G25+H25+I25 -> 8017.1873 | K25: =G25+H25+I25 -> 8017.1873 | L25: =IF(K25<=2000,(0),IF(K25<=4000,(K25*0.15)-300,IF(K25<=7000,(K25*0.2)-500,IF(K25<=10000,(K25*0.25)-850,IF(K25<=14000,(K25*0.3)-1350,IF(K25>14000,(K25*0.35)-2050)))))) -> 1154.2968 | M25: =F25*0.07 -> 355.8849 | N25: =F25*0.11 -> 559.2477 | O25: 2500 | P25: =L25+M25+O25 -> 4010.1817 | R25: =J25-P25+Q25 -> 4007.0056
A26: 21 | B26: Dagim Mengistu | C26: Driver | D26: Head Office | E26: 30 | F26: 14655.17 | G26: =+F26/30*E26 -> 14655.17 | I26: 3076.93 | J26: =G26+H26+I26 -> 17732.1 | K26: =G26+H26+I26 -> 17732.1 | L26: =IF(K26<=2000,(0),IF(K26<=4000,(K26*0.15)-300,IF(K26<=7000,(K26*0.2)-500,IF(K26<=10000,(K26*0.25)-850,IF(K26<=14000,(K26*0.3)-1350,IF(K26>14000,(K26*0.35)-2050)))))) -> 4156.235 | M26: =F26*0.07 -> 1025.8619 | N26: =F26*0.11 -> 1612.0687 | O26: 4000 | P26: =L26+M26+O26 -> 9182.0969 | Q26: =1000/30*E26 -> 1000 | R26: =J26-P26+Q26 -> 9550.0031
A27: 22 | B27: Dinar Kahisay Berhe | C27: SM | D27: Wessen | E27: 30 | F27: 20603.45 | G27: =+F27/30*E27 -> 20603.45 | I27: =1846.15*0 -> 0 | J27: =G27+H27+I27 -> 20603.45 | K27: =G27+H27+I27 -> 20603.45 | L27: =IF(K27<=2000,(0),IF(K27<=4000,(K27*0.15)-300,IF(K27<=7000,(K27*0.2)-500,IF(K27<=10000,(K27*0.25)-850,IF(K27<=14000,(K27*0.3)-1350,IF(K27>14000,(K27*0.35)-2050)))))) -> 5161.2075 | M27: =F27*0.07 -> 1442.2415 | N27: =F27*0.11 -> 2266.3795 | P27: =L27+M27+O27 -> 6603.449 | Q27: =2000/30*E27 -> 2000 | R27: =J27-P27+Q27 -> 16000.001
A28: 23 | B28: Eden Ambaw | C28: DSP | D28: Fiyelbet | E28: 30 | F28: 7573.53 | G28: =+F28/30*E28 -> 7573.53 | I28: =2857.14/30*E28 -> 2857.14 | J28: =G28+H28+I28 -> 10430.67 | K28: =G28+H28+I28 -> 10430.67 | L28: =IF(K28<=2000,(0),IF(K28<=4000,(K28*0.15)-300,IF(K28<=7000,(K28*0.2)-500,IF(K28<=10000,(K28*0.25)-850,IF(K28<=14000,(K28*0.3)-1350,IF(K28>14000,(K28*0.35)-2050)))))) -> 1779.201 | M28: =F28*0.07 -> 530.1471 | N28: =F28*0.11 -> 833.0883 | P28: =L28+M28+O28 -> 2309.3481 | Q28: =1000/30*E28 -> 1000 | R28: =J28-P28+Q28 -> 9121.3219
A29: 24 | B29: Emebet Belete | C29: Cleaner | D29: Summit | E29: 30 | F29: 2381.41 | G29: =+F29/30*E29 -> 2381.41 | J29: =G29+H29+I29 -> 2381.41 | K29: =G29+H29+I29 -> 2381.41 | L29: =IF(K29<=2000,(0),IF(K29<=4000,(K29*0.15)-300,IF(K29<=7000,(K29*0.2)-500,IF(K29<=10000,(K29*0.25)-850,IF(K29<=14000,(K29*0.3)-1350,IF(K29>14000,(K29*0.35)-2050)))))) -> 57.2115 | M29: =F29*0.07 -> 166.6987 | N29: =F29*0.11 -> 261.9551 | P29: =L29+M29+O29 -> 223.9102 | R29: =J29-P29+Q29 -> 2157.4998
A30: 25 | B30: Enat Fiseha | C30: Cleaner | D30: Kara | E30: 30 | F30: 1044.44 | G30: =+F30/30*E30 -> 1044.44 | J30: =G30+H30+I30 -> 1044.44 | K30: =G30+H30+I30 -> 1044.44 | L30: =IF(K30<=2000,(0),IF(K30<=4000,(K30*0.15)-300,IF(K30<=7000,(K30*0.2)-500,IF(K30<=10000,(K30*0.25)-850,IF(K30<=14000,(K30*0.3)-1350,IF(K30>14000,(K30*0.35)-2050)))))) -> 0 | M30: =F30*0.07 -> 73.1108 | N30: =F30*0.11 -> 114.8884 | P30: =L30+M30+O30 -> 73.1108 | R30: =J30-P30+Q30 -> 971.3292
A31: 26 | B31: Enatenesh Tezera | C31: Cleaner | D31: Kara | E31: 30 | F31: 1600 | G31: =+F31/30*E31 -> 1600 | J31: =G31+H31+I31 -> 1600 | K31: =G31+H31+I31 -> 1600 | L31: =IF(K31<=2000,(0),IF(K31<=4000,(K31*0.15)-300,IF(K31<=7000,(K31*0.2)-500,IF(K31<=10000,(K31*0.25)-850,IF(K31<=14000,(K31*0.3)-1350,IF(K31>14000,(K31*0.35)-2050)))))) -> 0 | M31: =F31*0.07 -> 112 | N31: =F31*0.11 -> 176 | P31: =L31+M31+O31 -> 112 | R31: =J31-P31+Q31 -> 1488
A32: 27 | B32: Ekram Hussen Argaw | C32: DSP | D32: H/mariam | E32: 30 | F32: 7573.53 | G32: =+F32/30*E32 -> 7573.53 | I32: =2857.14/30*E32 -> 2857.14 | J32: =G32+H32+I32 -> 10430.67 | K32: =G32+H32+I32 -> 10430.67 | L32: =IF(K32<=2000,(0),IF(K32<=4000,(K32*0.15)-300,IF(K32<=7000,(K32*0.2)-500,IF(K32<=10000,(K32*0.25)-850,IF(K32<=14000,(K32*0.3)-1350,IF(K32>14000,(K32*0.35)-2050)))))) -> 1779.201 | M32: =F32*0.07 -> 530.1471 | N32: =F32*0.11 -> 833.0883 | P32: =L32+M32+O32 -> 2309.3481 | Q32: =1000/30*E32 -> 1000 | R32: =J32-P32+Q32 -> 9121.3219
A33: 28 | B33: Eyob Girma Ketema | C33: BA coordinator/Ebu Sales | D33: Megenagna | E33: 30 | F33: 13730.16 | G33: =+F33/30*E33 -> 13730.16 | I33: 1517.71 | J33: =G33+H33+I33 -> 15247.87 | K33: =G33+H33+I33 -> 15247.87 | L33: =IF(K33<=2000,(0),IF(K33<=4000,(K33*0.15)-300,IF(K33<=7000,(K33*0.2)-500,IF(K33<=10000,(K33*0.25)-850,IF(K33<=14000,(K33*0.3)-1350,IF(K33>14000,(K33*0.35)-2050)))))) -> 3286.7545 | P33: =L33+M33+O33 -> 3286.7545 | Q33: 1000 | R33: =J33-P33+Q33 -> 12961.115
A34: 29 | B34: Fantu Hailemariam | C34: Cleaner | D34: Megenagna | E34: 30 | F34: 1832.35 | G34: =+F34/30*E34 -> 1832.35 | J34: =G34+H34+I34 -> 1832.35 | K34: =G34+H34+I34 -> 1832.35 | L34: =IF(K34<=2000,(0),IF(K34<=4000,(K34*0.15)-300,IF(K34<=7000,(K34*0.2)-500,IF(K34<=10000,(K34*0.25)-850,IF(K34<=14000,(K34*0.3)-1350,IF(K34>14000,(K34*0.35)-2050)))))) -> 0 | P34: =L34+M34+O34 -> 0 | R34: =J34-P34+Q34 -> 1832.35
A35: 30 | B35: Fasika Girma | C35: S.Accountant | D35: Kechene | E35: 30 | F35: 9044.12 | G35: =+F35/30*E35 -> 9044.12 | I35: =2788.86/30*E35 -> 2788.86 | J35: =G35+H35+I35 -> 11832.98 | K35: =G35+H35+I35 -> 11832.98 | L35: =IF(K35<=2000,(0),IF(K35<=4000,(K35*0.15)-300,IF(K35<=7000,(K35*0.2)-500,IF(K35<=10000,(K35*0.25)-850,IF(K35<=14000,(K35*0.3)-1350,IF(K35>14000,(K35*0.35)-2050)))))) -> 2199.894 | M35: =F35*0.07 -> 633.0884 | N35: =F35*0.11 -> 994.8532 | P35: =L35+M35+O35 -> 2832.9824 | Q35: 1000 | R35: =J35-P35+Q35 -> 9999.9976
A36: 31 | B36: Feruza Jemal | C36: S.Accountant | D36: 4KILO | E36: 30 | F36: 9044.12 | G36: =+F36/30*E36 -> 9044.12 | I36: =2788.86 -> 2788.86 | J36: =G36+H36+I36 -> 11832.98 | K36: =G36+H36+I36 -> 11832.98 | L36: =IF(K36<=2000,(0),IF(K36<=4000,(K36*0.15)-300,IF(K36<=7000,(K36*0.2)-500,IF(K36<=10000,(K36*0.25)-850,IF(K36<=14000,(K36*0.3)-1350,IF(K36>14000,(K36*0.35)-2050)))))) -> 2199.894 | M36: =F36*0.07 -> 633.0884 | N36: =F36*0.11 -> 994.8532 | P36: =L36+M36+O36 -> 2832.9824 | Q36: 1000 | R36: =J36-P36+Q36 -> 9999.9976
A37: 32 | B37: Frewoini Haile | C37: S.Accountant | D37: Shiromeda | E37: 30 | F37: 11108.37 | G37: =+F37/30*E37 -> 11108.37 | I37: =2857.14*1 -> 2857.14 | J37: =G37+H37+I37 -> 13965.51 | K37: =G37+H37+I37 -> 13965.51 | L37: =IF(K37<=2000,(0),IF(K37<=4000,(K37*0.15)-300,IF(K37<=7000,(K37*0.2)-500,IF(K37<=10000,(K37*0.25)-850,IF(K37<=14000,(K37*0.3)-1350,IF(K37>14000,(K37*0.35)-2050)))))) -> 2839.653 | M37: =F37*0.07 -> 777.5859 | N37: =F37*0.11 -> 1221.9207 | P37: =L37+M37+O37 -> 3617.2389 | Q37: =1000+1200 -> 2200 | R37: =J37-P37+Q37 -> 12548.271
A38: 33 | B38: Genet Girma | C38: Cleaner | D38: AyatTafo | E38: 30 | F38: 1612.9 | G38: =+F38/30*E38 -> 1612.9 | J38: =G38+H38+I38 -> 1612.9 | K38: =G38+H38+I38 -> 1612.9 | L38: =IF(K38<=2000,(0),IF(K38<=4000,(K38*0.15)-300,IF(K38<=7000,(K38*0.2)-500,IF(K38<=10000,(K38*0.25)-850,IF(K38<=14000,(K38*0.3)-1350,IF(K38>14000,(K38*0.35)-2050)))))) -> 0 | M38: =F38*0.07 -> 112.903 | N38: =F38*0.11 -> 177.419 | P38: =L38+M38+O38 -> 112.903 | R38: =J38-P38+Q38 -> 1499.997
A39: 34 | B39: Genet G/tsadik | C39: Cleaner | D39: Head Office | E39: 30 | F39: 5913.34 | G39: =+F39/30*E39 -> 5913.34 | J39: =G39+H39+I39 -> 5913.34 | K39: =G39+H39+I39 -> 5913.34 | L39: =IF(K39<=2000,(0),IF(K39<=4000,(K39*0.15)-300,IF(K39<=7000,(K39*0.2)-500,IF(K39<=10000,(K39*0.25)-850,IF(K39<=14000,(K39*0.3)-1350,IF(K39>14000,(K39*0.35)-2050)))))) -> 682.668 | P39: =L39+M39+O39 -> 682.668 | Q39: 2000 | R39: =J39-P39+Q39 -> 7230.672
A40: 35 | B40: Genet Legese Kuma | C40: Accountant | D40: Head Office | E40: 30 | F40: 18879.31 | G40: =+F40/30*E40 -> 18879.31 | J40: =G40+H40+I40 -> 18879.31 | K40: =G40+H40+I40 -> 18879.31 | L40: =IF(K40<=2000,(0),IF(K40<=4000,(K40*0.15)-300,IF(K40<=7000,(K40*0.2)-500,IF(K40<=10000,(K40*0.25)-850,IF(K40<=14000,(K40*0.3)-1350,IF(K40>14000,(K40*0.35)-2050)))))) -> 4557.7585 | M40: =F40*0.07 -> 1321.5517 | N40: =F40*0.11 -> 2076.7241 | P40: =L40+M40+O40 -> 5879.3102 | Q40: 1500 | R40: =J40-P40+Q40 -> 14500
A41: 36 | B41: Genzeb Degif | C41: BA coordinator | D41: Summit | E41: 30 | F41: 4794.52 | G41: =+F41/30*E41 -> 4794.52 | I41: =2654.34/30*E41 -> 2654.34 | J41: =G41+H41+I41 -> 7448.86 | K41: =G41+H41+I41 -> 7448.86 | L41: =IF(K41<=2000,(0),IF(K41<=4000,(K41*0.15)-300,IF(K41<=7000,(K41*0.2)-500,IF(K41<=10000,(K41*0.25)-850,IF(K41<=14000,(K41*0.3)-1350,IF(K41>14000,(K41*0.35)-2050)))))) -> 1012.215 | M41: =F41*0.07 -> 335.6164 | N41: =F41*0.11 -> 527.3972 | P41: =L41+M41+O41 -> 1347.8314 | Q41: =1000/30*E41 -> 1000 | R41: =J41-P41+Q41 -> 7101.0286
...

Sheet DSA
A1: LeapFrog Software Technology Africa PLC
A2: Payroll Sheet DSA Staff
A3: For the Month of Sene 2018
A4: No. | B4: Name of Employees | C4: Position | D4: Shop Name | E4: Working days | F4: Basic Salary | G4: Monthly Salary | H4: Commiss. /OT | I4: KPI | J4: Gross Salary | K4: Taxable Income | L4: Income Tax | M4: Pension 7% | N4: Pension 11% | O4: Shortage/ Loan | P4: Total Deduction | Q4: Transport & other allowance | R4: Net Pay | S4: sign
A5: 1 | B5: Abdi Sultan | C5: DSA Coordinator | D5: Ferencai | E5: 30 | F5: 9044.12 | G5: =+F5/30*E5 -> 9044.12 | H5: =4088+3858+3631 -> 11577 | I5: =2788.86 -> 2788.86 | J5: =G5+H5+I5 -> 23409.98 | K5: =G5+H5+I5 -> 23409.98 | L5: =IF(K5<=2000,(0),IF(K5<=4000,(K5*0.15)-300,IF(K5<=7000,(K5*0.2)-500,IF(K5<=10000,(K5*0.25)-850,IF(K5<=14000,(K5*0.3)-1350,IF(K5>14000,(K5*0.35)-2050)))))) -> 6143.493 | M5: =F5*0.07 -> 633.0884 | N5: =F5*0.11 -> 994.8532 | P5: =L5+M5+O5 -> 6776.5814 | Q5: 1500 | R5: =J5-P5+Q5 -> 18133.399
A6: 3 | B6: Adino Moges | C6: DSA Coordinator | D6: Shiromeda | E6: 30 | F6: 9044.12 | G6: =+F6/30*E6 -> 9044.12 | H6: 2393 | I6: =2788.86*0.5 -> 1394.43 | J6: =G6+H6+I6 -> 12831.55 | K6: =G6+H6+I6 -> 12831.55 | L6: =IF(K6<=2000,(0),IF(K6<=4000,(K6*0.15)-300,IF(K6<=7000,(K6*0.2)-500,IF(K6<=10000,(K6*0.25)-850,IF(K6<=14000,(K6*0.3)-1350,IF(K6>14000,(K6*0.35)-2050)))))) -> 2499.465 | M6: =F6*0.07 -> 633.0884 | N6: =F6*0.11 -> 994.8532 | P6: =L6+M6+O6 -> 3132.5534 | Q6: 1500 | R6: =J6-P6+Q6 -> 11198.997
A7: 5 | B7: Ayele Getahun | C7: DSA Coordinator | D7: BoleArabsa | E7: 30 | F7: 9044.12 | G7: =+F7/30*E7 -> 9044.12 | H7: =14260+8984 -> 23244 | I7: =2788.86 -> 2788.86 | J7: =G7+H7+I7 -> 35076.98 | K7: =G7+H7+I7 -> 35076.98 | L7: =IF(K7<=2000,(0),IF(K7<=4000,(K7*0.15)-300,IF(K7<=7000,(K7*0.2)-500,IF(K7<=10000,(K7*0.25)-850,IF(K7<=14000,(K7*0.3)-1350,IF(K7>14000,(K7*0.35)-2050)))))) -> 10226.943 | M7: =F7*0.07 -> 633.0884 | N7: =F7*0.11 -> 994.8532 | P7: =L7+M7+O7 -> 10860.031 | Q7: 1500 | R7: =J7-P7+Q7 -> 25716.949
A8: 6 | B8: Azazhu Gashaw | C8: DSA | D8: 4KILO | E8: 30 | F8: 9044.12 | G8: =+F8/30*E8 -> 9044.12 | H8: =3245+5462 -> 8707 | I8: =2788.86*0.5 -> 1394.43 | J8: =G8+H8+I8 -> 19145.55 | K8: =G8+H8+I8 -> 19145.55 | L8: =IF(K8<=2000,(0),IF(K8<=4000,(K8*0.15)-300,IF(K8<=7000,(K8*0.2)-500,IF(K8<=10000,(K8*0.25)-850,IF(K8<=14000,(K8*0.3)-1350,IF(K8>14000,(K8*0.35)-2050)))))) -> 4650.9425 | M8: =F8*0.07 -> 633.0884 | N8: =F8*0.11 -> 994.8532 | P8: =L8+M8+O8 -> 5284.0309 | Q8: 1500 | R8: =J8-P8+Q8 -> 15361.519
A9: 7 | B9: Belaynew Tesfa | C9: DSA | D9: AyatTafo | E9: 30 | F9: 9044.12 | G9: =+F9/30*E9 -> 9044.12 | H9: =5491+5190 -> 10681 | I9: =2788.86*0.5 -> 1394.43 | J9: =G9+H9+I9 -> 21119.55 | K9: =G9+H9+I9 -> 21119.55 | L9: =IF(K9<=2000,(0),IF(K9<=4000,(K9*0.15)-300,IF(K9<=7000,(K9*0.2)-500,IF(K9<=10000,(K9*0.25)-850,IF(K9<=14000,(K9*0.3)-1350,IF(K9>14000,(K9*0.35)-2050)))))) -> 5341.8425 | M9: =F9*0.07 -> 633.0884 | N9: =F9*0.11 -> 994.8532 | P9: =L9+M9+O9 -> 5974.9309 | Q9: 1500 | R9: =J9-P9+Q9 -> 16644.619
A10: 10 | B10: Biruk Asmare | C10: DSA Coordinator | D10: Meri AYAT | E10: 30 | F10: 9044.12 | G10: =+F10/30*E10 -> 9044.12 | H10: =2803+4959 -> 7762 | I10: =2788.86*0.5 -> 1394.43 | J10: =G10+H10+I10 -> 18200.55 | K10: =G10+H10+I10 -> 18200.55 | L10: =IF(K10<=2000,(0),IF(K10<=4000,(K10*0.15)-300,IF(K10<=7000,(K10*0.2)-500,IF(K10<=10000,(K10*0.25)-850,IF(K10<=14000,(K10*0.3)-1350,IF(K10>14000,(K10*0.35)-2050)))))) -> 4320.1925 | M10: =F10*0.07 -> 633.0884 | N10: =F10*0.11 -> 994.8532 | P10: =L10+M10+O10 -> 4953.2809 | Q10: 1500 | R10: =J10-P10+Q10 -> 14747.269
A11: 11 | B11: Getachew Altaseb | C11: DSA | D11: 6KILO | E11: 30 | F11: 9044.12 | G11: =+F11/30*E11 -> 9044.12 | H11: =1748+3357 -> 5105 | J11: =G11+H11+I11 -> 14149.12 | K11: =G11+H11+I11 -> 14149.12 | L11: =IF(K11<=2000,(0),IF(K11<=4000,(K11*0.15)-300,IF(K11<=7000,(K11*0.2)-500,IF(K11<=10000,(K11*0.25)-850,IF(K11<=14000,(K11*0.3)-1350,IF(K11>14000,(K11*0.35)-2050)))))) -> 2902.192 | P11: =L11+M11+O11 -> 2902.192 | R11: =J11-P11+Q11 -> 11246.928
A12: 12 | B12: Habtamu Shewaye | C12: DSA Coordinator | D12: Kara | E12: 24 | F12: 9044.12 | G12: =+F12/30*E12 -> 7235.296 | H12: =7373+4580 -> 11953 | I12: =2788.86*0.5 -> 1394.43 | J12: =G12+H12+I12 -> 20582.726 | K12: =G12+H12+I12 -> 20582.726 | L12: =IF(K12<=2000,(0),IF(K12<=4000,(K12*0.15)-300,IF(K12<=7000,(K12*0.2)-500,IF(K12<=10000,(K12*0.25)-850,IF(K12<=14000,(K12*0.3)-1350,IF(K12>14000,(K12*0.35)-2050)))))) -> 5153.9541 | M12: =F12*0.07 -> 633.0884 | N12: =F12*0.11 -> 994.8532 | P12: =L12+M12+O12 -> 5787.0425 | Q12: 1500 | R12: =J12-P12+Q12 -> 16295.684
A13: 13 | B13: Hassen Seid | C13: DSA | D13: Head Office | E13: 30 | F13: 8007.94 | G13: =+F13/30*E13 -> 8007.94 | I13: 2519.64 | J13: =G13+H13+I13 -> 10527.58 | K13: =G13+H13+I13 -> 10527.58 | L13: =IF(K13<=2000,(0),IF(K13<=4000,(K13*0.15)-300,IF(K13<=7000,(K13*0.2)-500,IF(K13<=10000,(K13*0.25)-850,IF(K13<=14000,(K13*0.3)-1350,IF(K13>14000,(K13*0.35)-2050)))))) -> 1808.274 | M13: =F13*0.07 -> 560.5558 | N13: =F13*0.11 -> 880.8734 | P13: =L13+M13+O13 -> 2368.8298 | Q13: 1000 | R13: =J13-P13+Q13 -> 9158.7502
A14: 15 | B14: Lelise Melkam | C14: DSA | D14: BoleArabsa | E14: 30 | F14: 4794.52 | G14: =+F14/30*E14 -> 4794.52 | I14: =2519.64 -> 2519.64 | J14: =G14+H14+I14 -> 7314.16 | K14: =G14+H14+I14 -> 7314.16 | L14: =IF(K14<=2000,(0),IF(K14<=4000,(K14*0.15)-300,IF(K14<=7000,(K14*0.2)-500,IF(K14<=10000,(K14*0.25)-850,IF(K14<=14000,(K14*0.3)-1350,IF(K14>14000,(K14*0.35)-2050)))))) -> 978.54 | M14: =F14*0.07 -> 335.6164 | N14: =F14*0.11 -> 527.3972 | P14: =L14+M14+O14 -> 1314.1564 | Q14: 1000 | R14: =J14-P14+Q14 -> 7000.0036
A15: 18 | B15: Mihret Worku | C15: DSA | D15: Summit | E15: 7 | F15: 9045.12 | G15: =+F15/30*E15 -> 2110.528 | J15: =G15+H15+I15 -> 2110.528 | K15: =G15+H15+I15 -> 2110.528 | L15: =IF(K15<=2000,(0),IF(K15<=4000,(K15*0.15)-300,IF(K15<=7000,(K15*0.2)-500,IF(K15<=10000,(K15*0.25)-850,IF(K15<=14000,(K15*0.3)-1350,IF(K15>14000,(K15*0.35)-2050)))))) -> 16.5792 | P15: =L15+M15+O15 -> 16.5792 | R15: =J15-P15+Q15 -> 2093.9488
A16: 21 | B16: Samuel Tesfaye | C16: DSA | D16: AYAT49 | E16: 30 | F16: 9044.12 | G16: =+F16/30*E16 -> 9044.12 | H16: =2735+2692 -> 5427 | I16: =2788.86*0.5 -> 1394.43 | J16: =G16+H16+I16 -> 15865.55 | K16: =G16+H16+I16 -> 15865.55 | L16: =IF(K16<=2000,(0),IF(K16<=4000,(K16*0.15)-300,IF(K16<=7000,(K16*0.2)-500,IF(K16<=10000,(K16*0.25)-850,IF(K16<=14000,(K16*0.3)-1350,IF(K16>14000,(K16*0.35)-2050)))))) -> 3502.9425 | M16: =F16*0.07 -> 633.0884 | N16: =F16*0.11 -> 994.8532 | P16: =L16+M16+O16 -> 4136.0309 | Q16: 1500 | R16: =J16-P16+Q16 -> 13229.519
A17: 22 | B17: Sekina Hassen | C17: DSA | D17: Kara | E17: 30 | F17: 4794.52 | G17: =+F17/30*E17 -> 4794.52 | H17: ='Performance Summary'!K4 -> 3249.81 | I17: =2519.64 -> 2519.64 | J17: =G17+H17+I17 -> 10563.97 | K17: =G17+H17+I17 -> 10563.97 | L17: =IF(K17<=2000,(0),IF(K17<=4000,(K17*0.15)-300,IF(K17<=7000,(K17*0.2)-500,IF(K17<=10000,(K17*0.25)-850,IF(K17<=14000,(K17*0.3)-1350,IF(K17>14000,(K17*0.35)-2050)))))) -> 1819.191 | M17: =F17*0.07 -> 335.6164 | N17: =F17*0.11 -> 527.3972 | P17: =L17+M17+O17 -> 2154.8074 | Q17: 1000 | R17: =J17-P17+Q17 -> 9409.1626
A18: 23 | B18: Solomon Dessie | C18: DSA | D18: H/mariam | E18: 30 | F18: 4794.52 | G18: =+F18/30*E18 -> 4794.52 | I18: =2519.64 -> 2519.64 | J18: =G18+H18+I18 -> 7314.16 | K18: =G18+H18+I18 -> 7314.16 | L18: =IF(K18<=2000,(0),IF(K18<=4000,(K18*0.15)-300,IF(K18<=7000,(K18*0.2)-500,IF(K18<=10000,(K18*0.25)-850,IF(K18<=14000,(K18*0.3)-1350,IF(K18>14000,(K18*0.35)-2050)))))) -> 978.54 | M18: =F18*0.07 -> 335.6164 | N18: =F18*0.11 -> 527.3972 | P18: =L18+M18+O18 -> 1314.1564 | Q18: 1000 | R18: =J18-P18+Q18 -> 7000.0036
A19: 24 | B19: Tigist Gedif | C19: DSA | D19: BoleArabsa | E19: 30 | F19: 9044.12 | G19: =+F19/30*E19 -> 9044.12 | H19: =281+5231 -> 5512 | I19: =2788.86 -> 2788.86 | J19: =G19+H19+I19 -> 17344.98 | K19: =G19+H19+I19 -> 17344.98 | L19: =IF(K19<=2000,(0),IF(K19<=4000,(K19*0.15)-300,IF(K19<=7000,(K19*0.2)-500,IF(K19<=10000,(K19*0.25)-850,IF(K19<=14000,(K19*0.3)-1350,IF(K19>14000,(K19*0.35)-2050)))))) -> 4020.743 | M19: =F19*0.07 -> 633.0884 | N19: =F19*0.11 -> 994.8532 | P19: =L19+M19+O19 -> 4653.8314 | Q19: 1500 | R19: =J19-P19+Q19 -> 14191.149
A20: 27 | B20: Deribe Nigussie | C20: DSA | D20: Aleltu | E20: 30 | F20: 6164.38 | G20: =+F20/30*E20 -> 6164.38 | H20: =7313+4857 -> 12170 | I20: 2610.96 | J20: =G20+H20+I20 -> 20945.34 | K20: =G20+H20+I20 -> 20945.34 | L20: =IF(K20<=2000,(0),IF(K20<=4000,(K20*0.15)-300,IF(K20<=7000,(K20*0.2)-500,IF(K20<=10000,(K20*0.25)-850,IF(K20<=14000,(K20*0.3)-1350,IF(K20>14000,(K20*0.35)-2050)))))) -> 5280.869 | M20: =F20*0.07 -> 431.5066 | N20: =F20*0.11 -> 678.0818 | P20: =L20+M20+O20 -> 5712.3756 | Q20: 1500 | R20: =J20-P20+Q20 -> 16732.964
A21: 28 | B21: Gete Getahun | C21: DSA | D21: Chacha | E21: 30 | F21: 6164.38 | G21: =+F21/30*E21 -> 6164.38 | H21: =9434+4689 -> 14123 | I21: 2610.96 | J21: =G21+H21+I21 -> 22898.34 | K21: =G21+H21+I21 -> 22898.34 | L21: =IF(K21<=2000,(0),IF(K21<=4000,(K21*0.15)-300,IF(K21<=7000,(K21*0.2)-500,IF(K21<=10000,(K21*0.25)-850,IF(K21<=14000,(K21*0.3)-1350,IF(K21>14000,(K21*0.35)-2050)))))) -> 5964.419 | M21: =F21*0.07 -> 431.5066 | N21: =F21*0.11 -> 678.0818 | P21: =L21+M21+O21 -> 6395.9256 | Q21: 1500 | R21: =J21-P21+Q21 -> 18002.414
A22: 29 | B22: Moges Nigusu | C22: DSA | D22: Chacha | E22: 8 | F22: 6164.38 | G22: =+F22/30*E22 -> 1643.8347 | H22: =2074 -> 2074 | I22: =1277.63*0 -> 0 | J22: =G22+H22+I22 -> 3717.8347 | K22: =G22+H22+I22 -> 3717.8347 | L22: =IF(K22<=2000,(0),IF(K22<=4000,(K22*0.15)-300,IF(K22<=7000,(K22*0.2)-500,IF(K22<=10000,(K22*0.25)-850,IF(K22<=14000,(K22*0.3)-1350,IF(K22>14000,(K22*0.35)-2050)))))) -> 257.6752 | M22: =F22*0.07 -> 431.5066 | N22: =F22*0.11 -> 678.0818 | P22: =L22+M22+O22 -> 689.1818 | Q22: =1500*0 -> 0 | R22: =J22-P22+Q22 -> 3028.6529
A23: 30 | B23: Teka Dejene | C23: DSA | D23: Chacha | E23: 30 | F23: 6164.38 | G23: =+F23/30*E23 -> 6164.38 | H23: 4685 | I23: 2610.96 | J23: =G23+H23+I23 -> 13460.34 | K23: =G23+H23+I23 -> 13460.34 | L23: =IF(K23<=2000,(0),IF(K23<=4000,(K23*0.15)-300,IF(K23<=7000,(K23*0.2)-500,IF(K23<=10000,(K23*0.25)-850,IF(K23<=14000,(K23*0.3)-1350,IF(K23>14000,(K23*0.35)-2050)))))) -> 2688.102 | P23: =L23+M23+O23 -> 2688.102 | Q23: 1500 | R23: =J23-P23+Q23 -> 12272.238
A24: 31 | B24: Eshetu Zewde | C24: DSA | D24: Tafo Mission | E24: 30 | F24: 9044.12 | G24: =+F24/30*E24 -> 9044.12 | H24: =7534+7184 -> 14718 | I24: =2788.86 -> 2788.86 | J24: =G24+H24+I24 -> 26550.98 | K24: =G24+H24+I24 -> 26550.98 | L24: =IF(K24<=2000,(0),IF(K24<=4000,(K24*0.15)-300,IF(K24<=7000,(K24*0.2)-500,IF(K24<=10000,(K24*0.25)-850,IF(K24<=14000,(K24*0.3)-1350,IF(K24>14000,(K24*0.35)-2050)))))) -> 7242.843 | M24: =F24*0.07 -> 633.0884 | N24: =F24*0.11 -> 994.8532 | P24: =L24+M24+O24 -> 7875.9314 | Q24: 1500 | R24: =J24-P24+Q24 -> 20175.049
A25: 32 | B25: Erena Gudeta | C25: DSA | D25: Tafo Mission | E25: 30 | F25: 9044.12 | G25: =+F25/30*E25 -> 9044.12 | H25: =3766+8582+8893 -> 21241 | I25: =2788.86 -> 2788.86 | J25: =G25+H25+I25 -> 33073.98 | K25: =G25+H25+I25 -> 33073.98 | L25: =IF(K25<=2000,(0),IF(K25<=4000,(K25*0.15)-300,IF(K25<=7000,(K25*0.2)-500,IF(K25<=10000,(K25*0.25)-850,IF(K25<=14000,(K25*0.3)-1350,IF(K25>14000,(K25*0.35)-2050)))))) -> 9525.893 | M25: =F25*0.07 -> 633.0884 | N25: =F25*0.11 -> 994.8532 | P25: =L25+M25+O25 -> 10158.981 | Q25: 1500 | R25: =J25-P25+Q25 -> 24414.999
A26: 33 | B26: Gebeyaw Aynalem | C26: DSA Coordinator | D26: Tafo | E26: 30 | F26: 9044.12 | G26: =+F26/30*E26 -> 9044.12 | H26: =3929+6686 -> 10615 | I26: =2788.86 -> 2788.86 | J26: =G26+H26+I26 -> 22447.98 | K26: =G26+H26+I26 -> 22447.98 | L26: =IF(K26<=2000,(0),IF(K26<=4000,(K26*0.15)-300,IF(K26<=7000,(K26*0.2)-500,IF(K26<=10000,(K26*0.25)-850,IF(K26<=14000,(K26*0.3)-1350,IF(K26>14000,(K26*0.35)-2050)))))) -> 5806.793 | M26: =F26*0.07 -> 633.0884 | N26: =F26*0.11 -> 994.8532 | P26: =L26+M26+O26 -> 6439.8814 | Q26: 1500 | R26: =J26-P26+Q26 -> 17508.099
A27: 34 | B27: Lakech Eshetu | C27: DSA | D27: Tafo | E27: 30 | F27: 9044.12 | G27: =+F27/30*E27 -> 9044.12 | H27: =1454+2734 -> 4188 | I27: =2788.86 -> 2788.86 | J27: =G27+H27+I27 -> 16020.98 | K27: =G27+H27+I27 -> 16020.98 | L27: =IF(K27<=2000,(0),IF(K27<=4000,(K27*0.15)-300,IF(K27<=7000,(K27*0.2)-500,IF(K27<=10000,(K27*0.25)-850,IF(K27<=14000,(K27*0.3)-1350,IF(K27>14000,(K27*0.35)-2050)))))) -> 3557.343 | M27: =F27*0.07 -> 633.0884 | N27: =F27*0.11 -> 994.8532 | P27: =L27+M27+O27 -> 4190.4314 | Q27: 1500 | R27: =J27-P27+Q27 -> 13330.549
A28: 35 | B28: Mahlet G/wolde | C28: DSA | D28: Hageremariam | E28: 30 | F28: 6164.38 | G28: =+F28/30*E28 -> 6164.38 | H28: =6204+4107 -> 10311 | I28: =1277.63*0 -> 0 | J28: =G28+H28+I28 -> 16475.38 | K28: =G28+H28+I28 -> 16475.38 | L28: =IF(K28<=2000,(0),IF(K28<=4000,(K28*0.15)-300,IF(K28<=7000,(K28*0.2)-500,IF(K28<=10000,(K28*0.25)-850,IF(K28<=14000,(K28*0.3)-1350,IF(K28>14000,(K28*0.35)-2050)))))) -> 3716.383 | M28: =F28*0.07 -> 431.5066 | N28: =F28*0.11 -> 678.0818 | P28: =L28+M28+O28 -> 4147.8896 | R28: =J28-P28+Q28 -> 12327.49
A29: 36 | B29: Arega Jenena | C29: DSA | D29: Sirti | E29: 30 | F29: 6164.38 | G29: =+F29/30*E29 -> 6164.38 | H29: =4673+4673 -> 9346 | I29: 1277.63 | J29: =G29+H29+I29 -> 16788.01 | K29: =G29+H29+I29 -> 16788.01 | L29: =IF(K29<=2000,(0),IF(K29<=4000,(K29*0.15)-300,IF(K29<=7000,(K29*0.2)-500,IF(K29<=10000,(K29*0.25)-850,IF(K29<=14000,(K29*0.3)-1350,IF(K29>14000,(K29*0.35)-2050)))))) -> 3825.8035 | M29: =F29*0.07 -> 431.5066 | N29: =F29*0.11 -> 678.0818 | P29: =L29+M29+O29 -> 4257.3101 | Q29: 1500 | R29: =J29-P29+Q29 -> 14030.7
A30: 37 | B30: Alem Aschenaki | C30: DSA | D30: Mendida | E30: 30 | F30: 6164.38 | G30: =+F30/30*E30 -> 6164.38 | H30: =8143+8142 -> 16285 | I30: 2610.96 | J30: =G30+H30+I30 -> 25060.34 | K30: =G30+H30+I30 -> 25060.34 | L30: =IF(K30<=2000,(0),IF(K30<=4000,(K30*0.15)-300,IF(K30<=7000,(K30*0.2)-500,IF(K30<=10000,(K30*0.25)-850,IF(K30<=14000,(K30*0.3)-1350,IF(K30>14000,(K30*0.35)-2050)))))) -> 6721.119 | M30: =F30*0.07 -> 431.5066 | N30: =F30*0.11 -> 678.0818 | P30: =L30+M30+O30 -> 7152.6256 | Q30: 1500 | R30: =J30-P30+Q30 -> 19407.714
A31: 38 | B31: Aman Nigusu | C31: DSA | D31: Mendida | E31: 30 | F31: 6164.38 | G31: =+F31/30*E31 -> 6164.38 | H31: =25132+12496 -> 37628 | I31: 2610.96 | J31: =G31+H31+I31 -> 46403.34 | K31: =G31+H31+I31 -> 46403.34 | L31: =IF(K31<=2000,(0),IF(K31<=4000,(K31*0.15)-300,IF(K31<=7000,(K31*0.2)-500,IF(K31<=10000,(K31*0.25)-850,IF(K31<=14000,(K31*0.3)-1350,IF(K31>14000,(K31*0.35)-2050)))))) -> 14191.169 | M31: =F31*0.07 -> 431.5066 | N31: =F31*0.11 -> 678.0818 | P31: =L31+M31+O31 -> 14622.676 | Q31: 1500 | R31: =J31-P31+Q31 -> 33280.664
A32: 39 | B32: Fikirte Abiye | C32: DSA | D32: Mendida | E32: 30 | F32: 6164.38 | G32: =+F32/30*E32 -> 6164.38 | H32: =21238+10576 -> 31814 | I32: 2610.96 | J32: =G32+H32+I32 -> 40589.34 | K32: =G32+H32+I32 -> 40589.34 | L32: =IF(K32<=2000,(0),IF(K32<=4000,(K32*0.15)-300,IF(K32<=7000,(K32*0.2)-500,IF(K32<=10000,(K32*0.25)-850,IF(K32<=14000,(K32*0.3)-1350,IF(K32>14000,(K32*0.35)-2050)))))) -> 12156.269 | M32: =F32*0.07 -> 431.5066 | N32: =F32*0.11 -> 678.0818 | P32: =L32+M32+O32 -> 12587.776 | Q32: 1500 | R32: =J32-P32+Q32 -> 29501.564
A33: 40 | B33: Bacha Wondu | C33: DSA | D33: Sendafa | E33: 30 | F33: 4794.52 | G33: =+F33/30*E33 -> 4794.52 | H33: =5958+5946 -> 11904 | I33: =2519.64*0.5 -> 1259.82 | J33: =G33+H33+I33 -> 17958.34 | K33: =G33+H33+I33 -> 17958.34 | L33: =IF(K33<=2000,(0),IF(K33<=4000,(K33*0.15)-300,IF(K33<=7000,(K33*0.2)-500,IF(K33<=10000,(K33*0.25)-850,IF(K33<=14000,(K33*0.3)-1350,IF(K33>14000,(K33*0.35)-2050)))))) -> 4235.419 | M33: =F33*0.07 -> 335.6164 | N33: =F33*0.11 -> 527.3972 | P33: =L33+M33+O33 -> 4571.0354 | Q33: 1500 | R33: =J33-P33+Q33 -> 14887.305
A34: 41 | B34: Birtukan Diriba | C34: DSA | D34: Sendafa Beke | E34: 30 | F34: 9044.12 | G34: =+F34/30*E34 -> 9044.12 | H34: ='Performance Summary'!K6 -> 8560.5 | I34: =2788.86 -> 2788.86 | J34: =G34+H34+I34 -> 20393.48 | K34: =G34+H34+I34 -> 20393.48 | L34: =IF(K34<=2000,(0),IF(K34<=4000,(K34*0.15)-300,IF(K34<=7000,(K34*0.2)-500,IF(K34<=10000,(K34*0.25)-850,IF(K34<=14000,(K34*0.3)-1350,IF(K34>14000,(K34*0.35)-2050)))))) -> 5087.718 | M34: =F34*0.07 -> 633.0884 | N34: =F34*0.11 -> 994.8532 | P34: =L34+M34+O34 -> 5720.8064 | Q34: 1500 | R34: =J34-P34+Q34 -> 16172.674
A35: 42 | B35: Yafet Abiy | C35: DSA | D35: Sendafa | E35: 30 | F35: 9044.12 | G35: =+F35/30*E35 -> 9044.12 | H35: 7064 | I35: =2788.86+7027 -> 9815.86 | J35: =G35+H35+I35 -> 25923.98 | K35: =G35+H35+I35 -> 25923.98 | L35: =IF(K35<=2000,(0),IF(K35<=4000,(K35*0.15)-300,IF(K35<=7000,(K35*0.2)-500,IF(K35<=10000,(K35*0.25)-850,IF(K35<=14000,(K35*0.3)-1350,IF(K35>14000,(K35*0.35)-2050)))))) -> 7023.393 | M35: =F35*0.07 -> 633.0884 | N35: =F35*0.11 -> 994.8532 | P35: =L35+M35+O35 -> 7656.4814 | Q35: 1500 | R35: =J35-P35+Q35 -> 19767.499
A36: 43 | B36: Shiferaw Gebre | C36: DSA | D36: Sheno | E36: 30 | F36: 6164.38 | G36: =+F36/30*E36 -> 6164.38 | H36: =17858+4601 -> 22459 | I36: =2610.96*0.5 -> 1305.48 | J36: =G36+H36+I36 -> 29928.86 | K36: =G36+H36+I36 -> 29928.86 | L36: =IF(K36<=2000,(0),IF(K36<=4000,(K36*0.15)-300,IF(K36<=7000,(K36*0.2)-500,IF(K36<=10000,(K36*0.25)-850,IF(K36<=14000,(K36*0.3)-1350,IF(K36>14000,(K36*0.35)-2050)))))) -> 8425.101 | M36: =F36*0.07 -> 431.5066 | N36: =F36*0.11 -> 678.0818 | P36: =L36+M36+O36 -> 8856.6076 | Q36: 1500 | R36: =J36-P36+Q36 -> 22572.252
A37: 44 | B37: Solomon Hailu | C37: DSA | D37: Sheno | E37: 30 | F37: 6164.38 | G37: =+F37/30*E37 -> 6164.38 | H37: =6931+8893 -> 15824 | I37: 2610.96 | J37: =G37+H37+I37 -> 24599.34 | K37: =G37+H37+I37 -> 24599.34 | L37: =IF(K37<=2000,(0),IF(K37<=4000,(K37*0.15)-300,IF(K37<=7000,(K37*0.2)-500,IF(K37<=10000,(K37*0.25)-850,IF(K37<=14000,(K37*0.3)-1350,IF(K37>14000,(K37*0.35)-2050)))))) -> 6559.769 | M37: =F37*0.07 -> 431.5066 | N37: =F37*0.11 -> 678.0818 | P37: =L37+M37+O37 -> 6991.2756 | Q37: 1500 | R37: =J37-P37+Q37 -> 19108.064
A38: Total | F38: =SUM(F5:F37) -> 248745.24 | G38: =SUM(G5:G37) -> 235481.28 | H38: =SUM(H5:H37) -> 350620.31 | I38: =SUM(I5:I37) -> 72691.53 | J38: =SUM(J5:J37) -> 658793.12 | K38: =SUM(K5:K37) -> 658793.12 | L38: =SUM(L5:L37) -> 166629.91 | M38: =SUM(M5:M37) -> 15714.413 | ... R38: =SUM(R5:R37) -> 517948.79
A40: Prepaired By | G40: Checked By:- | M40: Approved By:-
A41: Name :- _____________________________ | G41: Name :- ______________________________ | M41: Name :- ______________________________
...

Sheet EBU Department
A1: LeapFrog Software Technology Africa PLC
A2: Payroll Sheet EBU Staff
A3: For the Month of June 2026/Sene 2018
A4: No. | B4: Name of Employees | C4: Position | D4: Shop Name | E4: Working days | F4: Basic Salary | G4: Monthly Salary | H4: Commiss. /OT | I4: KPI | J4: Gross Salary | K4: Taxable Income | L4: Income Tax | M4: Pension 7% | N4: Pension 11% | O4: Shortage/ Loan | P4: Total Deduction | Q4: Transport & other allowance | R4: Net Pay | S4: sign
A6: 1 | B6: Abuye Behaylu | C6: FTTH teamleader | D6: Ayat49 | E6: 30 | F6: 9044.12 | G6: =+F6/30*E6 -> 9044.12 | I6: =5699.1 -> 5699.1 | J6: =G6+H6+I6 -> 14743.22 | K6: =G6+H6+I6 -> 14743.22 | L6: =IF(K6<=2000,(0),IF(K6<=4000,(K6*0.15)-300,IF(K6<=7000,(K6*0.2)-500,IF(K6<=10000,(K6*0.25)-850,IF(K6<=14000,(K6*0.3)-1350,IF(K6>14000,(K6*0.35)-2050)))))) -> 3110.127 | M6: =F6*0.07 -> 633.0884 | N6: =F6*0.11 -> 994.8532 | P6: =L6+M6+O6 -> 3743.2154 | Q6: =1000+1480 -> 2480 | R6: =J6-P6+Q6 -> 13480.005
A7: 2 | B7: Amanuel Dede | C7: Business Development mgt | D7: Head Office | E7: 30 | F7: 52500 | G7: =+F7/30*E7 -> 52500 | J7: =G7+H7+I7 -> 52500 | K7: =G7+H7+I7 -> 52500 | L7: =IF(K7<=2000,(0),IF(K7<=4000,(K7*0.15)-300,IF(K7<=7000,(K7*0.2)-500,IF(K7<=10000,(K7*0.25)-850,IF(K7<=14000,(K7*0.3)-1350,IF(K7>14000,(K7*0.35)-2050)))))) -> 16325 | M7: =F7*0.07 -> 3675 | N7: =F7*0.11 -> 5775 | O7: 10000 | P7: =L7+M7+O7 -> 30000 | Q7: 2000 | R7: =J7-P7+Q7 -> 24500
A8: 3 | B8: Anbel Haylome | C8: Outdoor Sales | D8: Bole Arabsa | E8: 15 | F8: 7533.33 | G8: =+F8/30*E8 -> 3766.665 | I8: =2680.95*0 -> 0 | J8: =G8+H8+I8 -> 3766.665 | K8: =G8+H8+I8 -> 3766.665 | L8: =IF(K8<=2000,(0),IF(K8<=4000,(K8*0.15)-300,IF(K8<=7000,(K8*0.2)-500,IF(K8<=10000,(K8*0.25)-850,IF(K8<=14000,(K8*0.3)-1350,IF(K8>14000,(K8*0.35)-2050)))))) -> 264.99975 | P8: =L8+M8+O8 -> 264.99975 | Q8: =1000/30*E8 -> 500 | R8: =J8-P8+Q8 -> 4001.6653
A9: 4 | B9: Ashenafi Abdi | C9: FTTH TeamLeader | D9: Abado | E9: 30 | F9: 9044.12 | G9: =+F9/30*E9 -> 9044.12 | I9: 5699.1 | J9: =G9+H9+I9 -> 14743.22 | K9: =G9+H9+I9 -> 14743.22 | L9: =IF(K9<=2000,(0),IF(K9<=4000,(K9*0.15)-300,IF(K9<=7000,(K9*0.2)-500,IF(K9<=10000,(K9*0.25)-850,IF(K9<=14000,(K9*0.3)-1350,IF(K9>14000,(K9*0.35)-2050)))))) -> 3110.127 | M9: =F9*0.07 -> 633.0884 | N9: =F9*0.11 -> 994.8532 | P9: =L9+M9+O9 -> 3743.2154 | Q9: =1000+740 -> 1740 | R9: =J9-P9+Q9 -> 12740.005
A10: 5 | B10: Bereket Alemante | C10: Outdoor Sales | D10: Bole Arabsa | E10: 18 | F10: 7533.33 | G10: =+F10/30*E10 -> 4519.998 | H10: 4914.35 | I10: =2680.95 -> 2680.95 | J10: =G10+H10+I10 -> 12115.298 | K10: =G10+H10+I10 -> 12115.298 | L10: =IF(K10<=2000,(0),IF(K10<=4000,(K10*0.15)-300,IF(K10<=7000,(K10*0.2)-500,IF(K10<=10000,(K10*0.25)-850,IF(K10<=14000,(K10*0.3)-1350,IF(K10>14000,(K10*0.35)-2050)))))) -> 2284.5894 | P10: =L10+M10+O10 -> 2284.5894 | Q10: 2200 | R10: =J10-P10+Q10 -> 12030.709 | S10: =5780-2200 -> 3580 | T10: =12030.71 -> 12030.71
A11: 6 | B11: Bezawit H/Michael | C11: Outdoor Sales | D11: Summit | E11: 18 | F11: 7533.33 | G11: =+F11/30*E11 -> 4519.998 | I11: =2680.95*0 -> 0 | J11: =G11+H11+I11 -> 4519.998 | K11: =G11+H11+I11 -> 4519.998 | L11: =IF(K11<=2000,(0),IF(K11<=4000,(K11*0.15)-300,IF(K11<=7000,(K11*0.2)-500,IF(K11<=10000,(K11*0.25)-850,IF(K11<=14000,(K11*0.3)-1350,IF(K11>14000,(K11*0.35)-2050)))))) -> 403.9996 | P11: =L11+M11+O11 -> 403.9996 | Q11: =1000/30*E11+740 -> 1340 | R11: =J11-P11+Q11 -> 5455.9984
A12: 7 | B12: Biniyam H/Gebriel | C12: FTTH TeamLeader | D12: Bole Arabsa | E12: 30 | F12: 9044.12 | G12: =+F12/30*E12 -> 9044.12 | H12: 5446.15 | I12: =5699.1 -> 5699.1 | J12: =G12+H12+I12 -> 20189.37 | K12: =G12+H12+I12 -> 20189.37 | L12: =IF(K12<=2000,(0),IF(K12<=4000,(K12*0.15)-300,IF(K12<=7000,(K12*0.2)-500,IF(K12<=10000,(K12*0.25)-850,IF(K12<=14000,(K12*0.3)-1350,IF(K12>14000,(K12*0.35)-2050)))))) -> 5016.2795 | P12: =L12+M12+O12 -> 5016.2795 | Q12: 2200 | R12: =J12-P12+Q12 -> 17373.091 | S12: =5740-2200 -> 3540 | T12: 17373.093
A13: 8 | B13: Birtukan Boja | C13: Outdoor Sales | D13: Abado | E13: 30 | F13: 7533.33 | G13: =+F13/30*E13 -> 7533.33 | I13: =2680.95*0 -> 0 | J13: =G13+H13+I13 -> 7533.33 | K13: =G13+H13+I13 -> 7533.33 | L13: =IF(K13<=2000,(0),IF(K13<=4000,(K13*0.15)-300,IF(K13<=7000,(K13*0.2)-500,IF(K13<=10000,(K13*0.25)-850,IF(K13<=14000,(K13*0.3)-1350,IF(K13>14000,(K13*0.35)-2050)))))) -> 1033.3325 | P13: =L13+M13+O13 -> 1033.3325 | Q13: =1000+370 -> 1370 | R13: =J13-P13+Q13 -> 7869.9975
A14: 9 | B14: Birtukan Worku | C14: Outdoor Sales | D14: Bole Arabsa | E14: 30 | F14: 7533.33 | G14: =+F14/30*E14 -> 7533.33 | H14: 5831.87 | I14: =2680.95 -> 2680.95 | J14: =G14+H14+I14 -> 16046.15 | K14: =G14+H14+I14 -> 16046.15 | L14: =IF(K14<=2000,(0),IF(K14<=4000,(K14*0.15)-300,IF(K14<=7000,(K14*0.2)-500,IF(K14<=10000,(K14*0.25)-850,IF(K14<=14000,(K14*0.3)-1350,IF(K14>14000,(K14*0.35)-2050)))))) -> 3566.1525 | P14: =L14+M14+O14 -> 3566.1525 | Q14: 2200 | R14: =J14-P14+Q14 -> 14679.998 | S14: =6180-2200 -> 3980 | T14: 14679.996
A15: 10 | B15: Degeye Derba | C15: Outdoor Sales | D15: Summit | E15: 30 | F15: 7533.33 | G15: =+F15/30*E15 -> 7533.33 | H15: 373.33 | I15: =2680.95*0 -> 0 | J15: =G15+H15+I15 -> 7906.66 | K15: =G15+H15+I15 -> 7906.66 | L15: =IF(K15<=2000,(0),IF(K15<=4000,(K15*0.15)-300,IF(K15<=7000,(K15*0.2)-500,IF(K15<=10000,(K15*0.25)-850,IF(K15<=14000,(K15*0.3)-1350,IF(K15>14000,(K15*0.35)-2050)))))) -> 1126.665 | P15: =L15+M15+O15 -> 1126.665 | Q15: 2200 | R15: =J15-P15+Q15 -> 8979.995 | S15: =2480-2200 -> 280 | T15: 8979.9975
A16: 11 | B16: Derbe Girma | C16: Outdoor Sales | D16: Abado | E16: 30 | F16: 7533.33 | G16: =+F16/30*E16 -> 7533.33 | H16: 866.72 | J16: =G16+H16+I16 -> 8400.05 | K16: =G16+H16+I16 -> 8400.05 | L16: =IF(K16<=2000,(0),IF(K16<=4000,(K16*0.15)-300,IF(K16<=7000,(K16*0.2)-500,IF(K16<=10000,(K16*0.25)-850,IF(K16<=14000,(K16*0.3)-1350,IF(K16>14000,(K16*0.35)-2050)))))) -> 1250.0125 | P16: =L16+M16+O16 -> 1250.0125 | Q16: 2200 | R16: =J16-P16+Q16 -> 9350.0375 | S16: =2850-2200 -> 650 | T16: 9349.9975
A17: 12 | B17: Eyerusalem Gesisa | C17: Outdoor Sales | D17: Summit | E17: 15 | F17: 7534.33 | G17: =+F17/30*E17 -> 3767.165 | I17: =2680.95*0 -> 0 | J17: =G17+H17+I17 -> 3767.165 | K17: =G17+H17+I17 -> 3767.165 | L17: =IF(K17<=2000,(0),IF(K17<=4000,(K17*0.15)-300,IF(K17<=7000,(K17*0.2)-500,IF(K17<=10000,(K17*0.25)-850,IF(K17<=14000,(K17*0.3)-1350,IF(K17>14000,(K17*0.35)-2050)))))) -> 265.07475 | P17: =L17+M17+O17 -> 265.07475 | Q17: =1000 -> 1000 | R17: =J17-P17+Q17 -> 4502.0903
A18: 13 | B18: Eyob Demillie | C18: Outdoor Sales | D18: Bole Arabsa | E18: 30 | F18: 7533.33 | G18: =+F18/30*E18 -> 7533.33 | H18: 1853.33 | J18: =G18+H18+I18 -> 9386.66 | K18: =G18+H18+I18 -> 9386.66 | L18: =IF(K18<=2000,(0),IF(K18<=4000,(K18*0.15)-300,IF(K18<=7000,(K18*0.2)-500,IF(K18<=10000,(K18*0.25)-850,IF(K18<=14000,(K18*0.3)-1350,IF(K18>14000,(K18*0.35)-2050)))))) -> 1496.665 | P18: =L18+M18+O18 -> 1496.665 | Q18: 2200 | R18: =J18-P18+Q18 -> 10089.995 | S18: =3590-2200 -> 1390 | T18: 10089.997
A19: 14 | B19: Firaol tsegayee | C19: Outdoor Sales | D19: Bole Arabsa | E19: 18 | F19: 7533.33 | G19: =+F19/30*E19 -> 4519.998 | I19: =2680.95*0 -> 0 | J19: =G19+H19+I19 -> 4519.998 | K19: =G19+H19+I19 -> 4519.998 | L19: =IF(K19<=2000,(0),IF(K19<=4000,(K19*0.15)-300,IF(K19<=7000,(K19*0.2)-500,IF(K19<=10000,(K19*0.25)-850,IF(K19<=14000,(K19*0.3)-1350,IF(K19>14000,(K19*0.35)-2050)))))) -> 403.9996 | P19: =L19+M19+O19 -> 403.9996 | Q19: =1000+370 -> 1370 | R19: =J19-P19+Q19 -> 5485.9984
A20: 15 | B20: Genet Fisha | C20: Outdoor Sales | D20: Bole Arabsa | E20: 30 | F20: 7533.33 | G20: =+F20/30*E20 -> 7533.33 | H20: 1853.33 | I20: =2680.95*0 -> 0 | J20: =G20+H20+I20 -> 9386.66 | K20: =G20+H20+I20 -> 9386.66 | L20: =IF(K20<=2000,(0),IF(K20<=4000,(K20*0.15)-300,IF(K20<=7000,(K20*0.2)-500,IF(K20<=10000,(K20*0.25)-850,IF(K20<=14000,(K20*0.3)-1350,IF(K20>14000,(K20*0.35)-2050)))))) -> 1496.665 | P20: =L20+M20+O20 -> 1496.665 | Q20: 2200 | R20: =J20-P20+Q20 -> 10089.995 | S20: =3590-2200 -> 1390 | T20: 10089.997
A21: 16 | B21: Hana Belay | C21: Outdoor Sales | D21: Bole Arabsa | E21: 24 | F21: 7533.33 | G21: =+F21/30*E21 -> 6026.664 | H21: 2346.66 | I21: =2680.95*0.5 -> 1340.475 | J21: =G21+H21+I21 -> 9713.799 | K21: =G21+H21+I21 -> 9713.799 | L21: =IF(K21<=2000,(0),IF(K21<=4000,(K21*0.15)-300,IF(K21<=7000,(K21*0.2)-500,IF(K21<=10000,(K21*0.25)-850,IF(K21<=14000,(K21*0.3)-1350,IF(K21>14000,(K21*0.35)-2050)))))) -> 1578.4498 | P21: =L21+M21+O21 -> 1578.4498 | Q21: 2200 | R21: =J21-P21+Q21 -> 10335.349 | S21: =3960-2200 -> 1760 | T21: 10335.354
A22: 17 | B22: Habtamu Assefa | C22: Outdoor Sales | D22: Abado | E22: 30 | F22: 7533.33 | G22: =+F22/30*E22 -> 7533.33 | H22: 1360 | I22: =2680.95*0 -> 0 | J22: =G22+H22+I22 -> 8893.33 | K22: =G22+H22+I22 -> 8893.33 | L22: =IF(K22<=2000,(0),IF(K22<=4000,(K22*0.15)-300,IF(K22<=7000,(K22*0.2)-500,IF(K22<=10000,(K22*0.25)-850,IF(K22<=14000,(K22*0.3)-1350,IF(K22>14000,(K22*0.35)-2050)))))) -> 1373.3325 | P22: =L22+M22+O22 -> 1373.3325 | Q22: 2200 | R22: =J22-P22+Q22 -> 9719.9975 | S22: =3220-2200 -> 1020 | T22: 9719.9975
A23: 18 | B23: Habtamu Tilahun | C23: Outdoor Sales | D23: Abado | E23: 30 | F23: 7533.33 | G23: =+F23/30*E23 -> 7533.33 | H23: 1213.55 | I23: =2680.95*0 -> 0 | J23: =G23+H23+I23 -> 8746.88 | K23: =G23+H23+I23 -> 8746.88 | L23: =IF(K23<=2000,(0),IF(K23<=4000,(K23*0.15)-300,IF(K23<=7000,(K23*0.2)-500,IF(K23<=10000,(K23*0.25)-850,IF(K23<=14000,(K23*0.3)-1350,IF(K23>14000,(K23*0.35)-2050)))))) -> 1336.72 | P23: =L23+M23+O23 -> 1336.72 | Q23: 2200 | R23: =J23-P23+Q23 -> 9610.16 | S23: =3110-2200 -> 910 | T23: 9609.9975
A24: 19 | B24: Haymanot Teferi | C24: Outdoor Sales | D24: Summit | E24: 30 | F24: 7533.33 | G24: =+F24/30*E24 -> 7533.33 | H24: 2805.27 | I24: =2680.95*0.5 -> 1340.475 | J24: =G24+H24+I24 -> 11679.075 | K24: =G24+H24+I24 -> 11679.075 | L24: =IF(K24<=2000,(0),IF(K24<=4000,(K24*0.15)-300,IF(K24<=7000,(K24*0.2)-500,IF(K24<=10000,(K24*0.25)-850,IF(K24<=14000,(K24*0.3)-1350,IF(K24>14000,(K24*0.35)-2050)))))) -> 2153.7225 | P24: =L24+M24+O24 -> 2153.7225 | Q24: 2200 | R24: =J24-P24+Q24 -> 11725.353 | S24: =4220-2200 -> 2020 | T24: 11725.354
A25: 20 | B25: Helen Ashagre | C25: Outdoor Sales | D25: Bole Arabsa | E25: 30 | F25: 7533.33 | G25: =+F25/30*E25 -> 7533.33 | H25: 5093.41 | I25: =2680.95 -> 2680.95 | J25: =G25+H25+I25 -> 15307.69 | K25: =G25+H25+I25 -> 15307.69 | L25: =IF(K25<=2000,(0),IF(K25<=4000,(K25*0.15)-300,IF(K25<=7000,(K25*0.2)-500,IF(K25<=10000,(K25*0.25)-850,IF(K25<=14000,(K25*0.3)-1350,IF(K25>14000,(K25*0.35)-2050)))))) -> 3307.6915 | P25: =L25+M25+O25 -> 3307.6915 | Q25: 2200 | R25: =J25-P25+Q25 -> 14199.998 | S25: =5700-2200 -> 3500 | T25: 14199.996
A26: 21 | B26: Henok Asnake | C26: Outdoor Sales | D26: Bole Arabsa | E26: 30 | F26: 7533.33 | G26: =+F26/30*E26 -> 7533.33 | H26: 2200 | I26: =2680.95*0 -> 0 | J26: =G26+H26+I26 -> 9733.33 | K26: =G26+H26+I26 -> 9733.33 | L26: =IF(K26<=2000,(0),IF(K26<=4000,(K26*0.15)-300,IF(K26<=7000,(K26*0.2)-500,IF(K26<=10000,(K26*0.25)-850,IF(K26<=14000,(K26*0.3)-1350,IF(K26>14000,(K26*0.35)-2050)))))) -> 1583.3325 | P26: =L26+M26+O26 -> 1583.3325 | Q26: 2200 | R26: =J26-P26+Q26 -> 10349.997 | S26: =3850-2200 -> 1650 | T26: 10349.997
A27: 22 | B27: Hermela Chalachew | C27: Outdoor Sales | D27: Bole Arabsa | E27: 30 | F27: 7533.33 | G27: =+F27/30*E27 -> 7533.33 | H27: 7539.56 | I27: =2680.95 -> 2680.95 | J27: =G27+H27+I27 -> 17753.84 | K27: =G27+H27+I27 -> 17753.84 | L27: =IF(K27<=2000,(0),IF(K27<=4000,(K27*0.15)-300,IF(K27<=7000,(K27*0.2)-500,IF(K27<=10000,(K27*0.25)-850,IF(K27<=14000,(K27*0.3)-1350,IF(K27>14000,(K27*0.35)-2050)))))) -> 4163.844 | P27: =L27+M27+O27 -> 4163.844 | Q27: 2200 | R27: =J27-P27+Q27 -> 15789.996 | S27: =7290-2200 -> 5090 | T27: 15789.996
A28: 23 | B28: Hiwot Getu | C28: Outdoor Sales | D28: Summit | E28: 28 | F28: 7533.33 | G28: =+F28/30*E28 -> 7031.108 | I28: =2680.95*0 -> 0 | J28: =G28+H28+I28 -> 7031.108 | K28: =G28+H28+I28 -> 7031.108 | L28: =IF(K28<=2000,(0),IF(K28<=4000,(K28*0.15)-300,IF(K28<=7000,(K28*0.2)-500,IF(K28<=10000,(K28*0.25)-850,IF(K28<=14000,(K28*0.3)-1350,IF(K28>14000,(K28*0.35)-2050)))))) -> 907.777 | P28: =L28+M28+O28 -> 907.777 | Q28: =1000+1110 -> 2110 | R28: =J28-P28+Q28 -> 8233.331
A29: 24 | B29: Kalkidan Tafese | C29: Outdoor Sales | D29: Summit | E29: 30 | F29: 7533.33 | G29: =+F29/30*E29 -> 7533.33 | H29: 3490.98 | I29: =2680.95*0.5 -> 1340.475 | J29: =G29+H29+I29 -> 12364.785 | K29: =G29+H29+I29 -> 12364.785 | L29: =IF(K29<=2000,(0),IF(K29<=4000,(K29*0.15)-300,IF(K29<=7000,(K29*0.2)-500,IF(K29<=10000,(K29*0.25)-850,IF(K29<=14000,(K29*0.3)-1350,IF(K29>14000,(K29*0.35)-2050)))))) -> 2359.4355 | P29: =L29+M29+O29 -> 2359.4355 | Q29: 2200 | R29: =J29-P29+Q29 -> 12205.35 | S29: =4700-2200 -> 2500 | T29: 12205.354
A30: 25 | B30: Mastewal Gullat | C30: Outdoor Sales | D30: Bole Arabsa | E30: 30 | F30: 7533.33 | G30: =+F30/30*E30 -> 7533.33 | I30: =2680.95 -> 2680.95 | J30: =G30+H30+I30 -> 10214.28 | K30: =G30+H30+I30 -> 10214.28 | L30: =IF(K30<=2000,(0),IF(K30<=4000,(K30*0.15)-300,IF(K30<=7000,(K30*0.2)-500,IF(K30<=10000,(K30*0.25)-850,IF(K30<=14000,(K30*0.3)-1350,IF(K30>14000,(K30*0.35)-2050)))))) -> 1714.284 | P30: =L30+M30+O30 -> 1714.284 | Q30: =1000+140 -> 1140 | R30: =J30-P30+Q30 -> 9639.996
A31: 26 | B31: Melat Taye | C31: Outdoor Sales | D31: Abado | E31: 30 | F31: 7533.33 | G31: =+F31/30*E31 -> 7533.33 | H31: 2962.41 | I31: =2680.95*0.5 -> 1340.475 | J31: =G31+H31+I31 -> 11836.215 | K31: =G31+H31+I31 -> 11836.215 | L31: =IF(K31<=2000,(0),IF(K31<=4000,(K31*0.15)-300,IF(K31<=7000,(K31*0.2)-500,IF(K31<=10000,(K31*0.25)-850,IF(K31<=14000,(K31*0.3)-1350,IF(K31>14000,(K31*0.35)-2050)))))) -> 2200.8645 | P31: =L31+M31+O31 -> 2200.8645 | Q31: 2200 | R31: =J31-P31+Q31 -> 11835.351 | S31: =4330-2200 -> 2130 | T31: 11835.354
A32: 28 | B32: Mistire Amezenechi | C32: Outdoor Sales | D32: Summit | E32: 18 | F32: 7533.33 | G32: =+F32/30*E32 -> 4519.998 | I32: =2680.95*0 -> 0 | J32: =G32+H32+I32 -> 4519.998 | K32: =G32+H32+I32 -> 4519.998 | L32: =IF(K32<=2000,(0),IF(K32<=4000,(K32*0.15)-300,IF(K32<=7000,(K32*0.2)-500,IF(K32<=10000,(K32*0.25)-850,IF(K32<=14000,(K32*0.3)-1350,IF(K32>14000,(K32*0.35)-2050)))))) -> 403.9996 | P32: =L32+M32+O32 -> 403.9996 | Q32: =1000+370 -> 1370 | R32: =J32-P32+Q32 -> 5485.9984
A33: 29 | B33: Mihiret Sisay | C33: Outdoor Sales | D33: Abado | E33: 30 | F33: 7533.33 | G33: =+F33/30*E33 -> 7533.33 | I33: =2680.95*0 -> 0 | J33: =G33+H33+I33 -> 7533.33 | K33: =G33+H33+I33 -> 7533.33 | L33: =IF(K33<=2000,(0),IF(K33<=4000,(K33*0.15)-300,IF(K33<=7000,(K33*0.2)-500,IF(K33<=10000,(K33*0.25)-850,IF(K33<=14000,(K33*0.3)-1350,IF(K33>14000,(K33*0.35)-2050)))))) -> 1033.3325 | P33: =L33+M33+O33 -> 1033.3325 | Q33: =1000+740 -> 1740 | R33: =J33-P33+Q33 -> 8239.9975
A34: 31 | B34: Rehima Senbti | C34: Outdoor Sales | D34: Summit | E34: 18 | F34: 7532.33 | G34: =+F34/30*E34 -> 4519.398 | I34: =2680.95*0 -> 0 | J34: =G34+H34+I34 -> 4519.398 | K34: =G34+H34+I34 -> 4519.398 | L34: =IF(K34<=2000,(0),IF(K34<=4000,(K34*0.15)-300,IF(K34<=7000,(K34*0.2)-500,IF(K34<=10000,(K34*0.25)-850,IF(K34<=14000,(K34*0.3)-1350,IF(K34>14000,(K34*0.35)-2050)))))) -> 403.8796 | P34: =L34+M34+O34 -> 403.8796 | Q34: =1000+370 -> 1370 | R34: =J34-P34+Q34 -> 5485.5184
A35: 32 | B35: Samrawit Chale | C35: Outdoor Sales | D35: Bole Arabsa | E35: 23 | F35: 7532.33 | G35: =+F35/30*E35 -> 5774.7863 | I35: =2680.95*0 -> 0 | J35: =G35+H35+I35 -> 5774.7863 | K35: =G35+H35+I35 -> 5774.7863 | L35: =IF(K35<=2000,(0),IF(K35<=4000,(K35*0.15)-300,IF(K35<=7000,(K35*0.2)-500,IF(K35<=10000,(K35*0.25)-850,IF(K35<=14000,(K35*0.3)-1350,IF(K35>14000,(K35*0.35)-2050)))))) -> 654.95727 | P35: =L35+M35+O35 -> 654.95727 | Q35: =1000/30*E35+1110 -> 1876.6667 | R35: =J35-P35+Q35 -> 6996.4957
A36: 34 | B36: Sena Debebe | C36: Outdoor Sales | D36: Summit | E36: 18 | F36: 7533.33 | G36: =+F36/30*E36 -> 4519.998 | I36: =2680.95*0 -> 0 | J36: =G36+H36+I36 -> 4519.998 | K36: =G36+H36+I36 -> 4519.998 | L36: =IF(K36<=2000,(0),IF(K36<=4000,(K36*0.15)-300,IF(K36<=7000,(K36*0.2)-500,IF(K36<=10000,(K36*0.25)-850,IF(K36<=14000,(K36*0.3)-1350,IF(K36>14000,(K36*0.35)-2050)))))) -> 403.9996 | P36: =L36+M36+O36 -> 403.9996 | Q36: =1000+1370 -> 2370 | R36: =J36-P36+Q36 -> 6485.9984
A37: 35 | B37: Solomon Wondesen | C37: Outdoor Sales | D37: Summit | E37: 43 | F37: 7533.33 | G37: =+F37/30*E37 -> 10797.773 | H37: 1019.04 | I37: =2680.95*0 -> 0 | J37: =G37+H37+I37 -> 11816.813 | K37: =G37+H37+I37 -> 11816.813 | L37: =IF(K37<=2000,(0),IF(K37<=4000,(K37*0.15)-300,IF(K37<=7000,(K37*0.2)-500,IF(K37<=10000,(K37*0.25)-850,IF(K37<=14000,(K37*0.3)-1350,IF(K37>14000,(K37*0.35)-2050)))))) -> 2195.0439 | P37: =L37+M37+O37 -> 2195.0439 | Q37: 2200 | R37: =J37-P37+Q37 -> 11821.769 | S37: =2913.33-2200 -> 713.33 | T37: 11821.774
A38: 36 | B38: Temesgen Asefa | C38: Outdoor Sales | D38: Abado | E38: 30 | F38: 7533.33 | G38: =+F38/30*E38 -> 7533.33 | H38: 3490.98 | I38: =2680.95*0.5 -> 1340.475 | J38: =G38+H38+I38 -> 12364.785 | K38: =G38+H38+I38 -> 12364.785 | L38: =IF(K38<=2000,(0),IF(K38<=4000,(K38*0.15)-300,IF(K38<=7000,(K38*0.2)-500,IF(K38<=10000,(K38*0.25)-850,IF(K38<=14000,(K38*0.3)-1350,IF(K38>14000,(K38*0.35)-2050)))))) -> 2359.4355 | P38: =L38+M38+O38 -> 2359.4355 | Q38: 2200 | R38: =J38-P38+Q38 -> 12205.35 | S38: =4700-2200 -> 2500 | T38: 12205.354
A39: 37 | B39: Temesgen Gubena | C39: Outdoor Sales | D39: Summit | E39: 30 | F39: 7533.33 | G39: =+F39/30*E39 -> 7533.33 | H39: 2962.41 | I39: =2680.95*0.5 -> 1340.475 | J39: =G39+H39+I39 -> 11836.215 | K39: =G39+H39+I39 -> 11836.215 | L39: =IF(K39<=2000,(0),IF(K39<=4000,(K39*0.15)-300,IF(K39<=7000,(K39*0.2)-500,IF(K39<=10000,(K39*0.25)-850,IF(K39<=14000,(K39*0.3)-1350,IF(K39>14000,(K39*0.35)-2050)))))) -> 2200.8645 | P39: =L39+M39+O39 -> 2200.8645 | Q39: 2200 | R39: =J39-P39+Q39 -> 11835.351 | S39: =4330-2200 -> 2130 | T39: 11835.354
A40: 38 | B40: Tigist Admasu | C40: Outdoor Sales | D40: Abado | E40: 30 | F40: 7533.33 | G40: =+F40/30*E40 -> 7533.33 | H40: 4019.55 | I40: =2680.95*0.5 -> 1340.475 | J40: =G40+H40+I40 -> 12893.355 | K40: =G40+H40+I40 -> 12893.355 | L40: =IF(K40<=2000,(0),IF(K40<=4000,(K40*0.15)-300,IF(K40<=7000,(K40*0.2)-500,IF(K40<=10000,(K40*0.25)-850,IF(K40<=14000,(K40*0.3)-1350,IF(K40>14000,(K40*0.35)-2050)))))) -> 2518.0065 | P40: =L40+M40+O40 -> 2518.0065 | Q40: 2200 | R40: =J40-P40+Q40 -> 12575.349 | S40: =5070-2200 -> 2870 | T40: 12575.354
A41: 40 | B41: Tsion Fikeru | C41: Outdoor Sales | D41: Bole Arabsa | E41: 30 | F41: 7533.33 | G41: =+F41/30*E41 -> 7533.33 | H41: 11524.18 | I41: =2680.95 -> 2680.95 | J41: =G41+H41+I41 -> 21738.46 | K41: =G41+H41+I41 -> 21738.46 | L41: =IF(K41<=2000,(0),IF(K41<=4000,(K41*0.15)-300,IF(K41<=7000,(K41*0.2)-500,IF(K41<=10000,(K41*0.25)-850,IF(K41<=14000,(K41*0.3)-1350,IF(K41>14000,(K41*0.35)-2050)))))) -> 5558.461 | P41: =L41+M41+O41 -> 5558.461 | Q41: 2200 | R41: =J41-P41+Q41 -> 18379.999 | S41: =9880-2200 -> 7680 | T41: 18379.996
...

Sheet Aleletu
A1: LeapFrog Software Technology Africa PLC
A2: Payroll Sheet Aleltu shop
A3: For the Month of Sene 2018
A4: No. | B4: Name of Employees | C4: Position | D4: Work place | E4: Working days | F4: Basic Salary | G4: Monthly Salary | H4: Commiss. /OT | I4: KPI | J4: Gross Salary | K4: Taxable Income | L4: Income Tax | M4: Pension 7% | N4: Pension 11% | O4: Shortage/ Loan | P4: Total Deduction | Q4: Transport & other allowance | R4: Net Pay | S4: sign
A5: 1 | B5: Fana Abebe | C5: DSP | D5: Aleltu | E5: 30 | F5: 3176.47 | G5: =+F5/30*E5 -> 3176.47 | J5: =G5+H5+I5 -> 3176.47 | K5: =G5+H5+I5 -> 3176.47 | L5: =IF(K5<=2000,(0),IF(K5<=4000,(K5*0.15)-300,IF(K5<=7000,(K5*0.2)-500,IF(K5<=10000,(K5*0.25)-850,IF(K5<=14000,(K5*0.3)-1350,IF(K5>14000,(K5*0.35)-2050)))))) -> 176.4705 | P5: =L5+M5+O5 -> 176.4705 | R5: =J5-P5+Q5 -> 2999.9995
A6: 2 | B6: Getenet Worku | C6: Shop SV | D6: Aleltu | E6: 30 | F6: 9044.12 | G6: =+F6/30*E6 -> 9044.12 | H6: 16 | I6: =2788.86/30*E6 -> 2788.86 | J6: =G6+H6+I6 -> 11848.98 | K6: =G6+H6+I6 -> 11848.98 | L6: =IF(K6<=2000,(0),IF(K6<=4000,(K6*0.15)-300,IF(K6<=7000,(K6*0.2)-500,IF(K6<=10000,(K6*0.25)-850,IF(K6<=14000,(K6*0.3)-1350,IF(K6>14000,(K6*0.35)-2050)))))) -> 2204.694 | M6: =F6*0.07 -> 633.0884 | N6: =F6*0.11 -> 994.8532 | P6: =L6+M6+O6 -> 2837.7824 | Q6: 1000 | R6: =J6-P6+Q6 -> 10011.198
A7: 3 | B7: Hana Bulo Bekele | C7: DSP | D7: Aleltu | E7: 30 | F7: 7573.53 | G7: =+F7/30*E7 -> 7573.53 | I7: =2683.83/30*E7 -> 2683.83 | J7: =G7+H7+I7 -> 10257.36 | K7: =G7+H7+I7 -> 10257.36 | L7: =IF(K7<=2000,(0),IF(K7<=4000,(K7*0.15)-300,IF(K7<=7000,(K7*0.2)-500,IF(K7<=10000,(K7*0.25)-850,IF(K7<=14000,(K7*0.3)-1350,IF(K7>14000,(K7*0.35)-2050)))))) -> 1727.208 | M7: =F7*0.07 -> 530.1471 | N7: =F7*0.11 -> 833.0883 | P7: =L7+M7+O7 -> 2257.3551 | R7: =J7-P7+Q7 -> 8000.0049
A8: Total | F8: =SUM(F5:F7) -> 19794.12 | G8: =SUM(G5:G7) -> 19794.12 | H8: =SUM(H5:H7) -> 16 | I8: =SUM(I5:I7) -> 5472.69 | J8: =SUM(J5:J7) -> 25282.81 | K8: =SUM(K5:K7) -> 25282.81 | L8: =SUM(L5:L7) -> 4108.3725 | M8: =SUM(M5:M7) -> 1163.2355 | ... R8: =SUM(R5:R7) -> 21011.202
A10: Prepaired By | G10: Checked By:- | M10: Approved By:-
A11: Name :- _____________________________ | G11: Name :- ______________________________ | M11: Name :- ______________________________
A12: Sign :- ______________________________ | G12: Sign :- ________________________________ | M12: Sign :- ________________________________
A13: Date:- _____________________________ | G13: Date:- _______________________________ | M13: Date:- _______________________________

Sheet Chacha
A1: LeapFrog Software Technology Africa PLC
A2: Payroll Sheet Chacha shop
A3: For the Month of Sene 2018
A5: No. | B5: Name of Employees | C5: Position | D5: Work place | E5: Working days | F5: Basic Salary | G5: Monthly Salary | H5: Commiss. /OT | I5: KPI | J5: Gross Salary | K5: Taxable Income | L5: Income Tax | M5: Pension 7% | N5: Pension 11% | O5: Shortage/ Loan | P5: Total Deduction | Q5: Transport & other allowance | R5: Net Pay | S5: sign
A6: 1 | B6: Fanose Tesfaye | C6: DSP | D6: Chacha | E6: 30 | F6: 7573.53 | G6: =+F6/30*E6 -> 7573.53 | I6: =2683.83/30*E6 -> 2683.83 | J6: =G6+H6+I6 -> 10257.36 | K6: =G6+H6+I6 -> 10257.36 | L6: =IF(K6<=2000,(0),IF(K6<=4000,(K6*0.15)-300,IF(K6<=7000,(K6*0.2)-500,IF(K6<=10000,(K6*0.25)-850,IF(K6<=14000,(K6*0.3)-1350,IF(K6>14000,(K6*0.35)-2050)))))) -> 1727.208 | M6: =F6*0.07 -> 530.1471 | N6: =F6*0.11 -> 833.0883 | P6: =L6+M6+O6 -> 2257.3551 | Q6: =1000/30*E6 -> 1000 | R6: =J6-P6+Q6 -> 9000.0049
